2021-05-03 08:00:35,193 [ERROR] 14061 140326341412672 /home/pycheck/src/pycheck/pycheck/lib/python3.6/site-packages/django/utils/log.py:230 Internal Server Error: /skill/upload/heku/
Traceback (most recent call last):
  File "/home/pycheck/src/pycheck/pycheck/lib/python3.6/site-packages/django/core/handlers/exception.py", line 47, in inner
    response = get_response(request)
  File "/home/pycheck/src/pycheck/pycheck/lib/python3.6/site-packages/django/core/handlers/base.py", line 181, in _get_response
    response = wrapped_callback(request, *callback_args, **callback_kwargs)
  File "/home/pycheck/src/pycheck/skill/views.py", line 79, in upload
    username, question_number, question_level, answer_time, score = ocr(file_name)
  File "/home/pycheck/src/pycheck/skill/views.py", line 30, in ocr
    Image.open(f"/Users/akira/Desktop/local/develop/pycheck/media/{str(image_path)}"),
  File "/home/pycheck/src/pycheck/pycheck/lib/python3.6/site-packages/PIL/Image.py", line 2891, in open
    fp = builtins.open(filename, "rb")
FileNotFoundError: [Errno 2] No such file or directory: '/Users/akira/Desktop/local/develop/pycheck/media/Screen_Shot_2021-05-03_AT_8.00.29.png'
2021-05-03 08:13:51,536 [WARNING] 14061 140326341412672 /home/pycheck/src/pycheck/pycheck/lib/python3.6/site-packages/django/utils/log.py:230 Not Found: /ecp/Current/exporttool/microsoft.exchange.ediscovery.exporttool.application
2021-05-03 08:20:36,069 [ERROR] 14507 140578161735488 /home/pycheck/src/pycheck/pycheck/lib/python3.6/site-packages/django/utils/log.py:230 Internal Server Error: /skill/upload/heku/
Traceback (most recent call last):
  File "/home/pycheck/src/pycheck/pycheck/lib/python3.6/site-packages/django/core/handlers/exception.py", line 47, in inner
    response = get_response(request)
  File "/home/pycheck/src/pycheck/pycheck/lib/python3.6/site-packages/django/core/handlers/base.py", line 181, in _get_response
    response = wrapped_callback(request, *callback_args, **callback_kwargs)
  File "/home/pycheck/src/pycheck/skill/views.py", line 79, in upload
    username, question_number, question_level, answer_time, score = ocr(file_name)
  File "/home/pycheck/src/pycheck/skill/views.py", line 30, in ocr
    Image.open(f"/Users/akira/Desktop/local/develop/pycheck/media/{str(image_path)}"),
  File "/home/pycheck/src/pycheck/pycheck/lib/python3.6/site-packages/PIL/Image.py", line 2891, in open
    fp = builtins.open(filename, "rb")
FileNotFoundError: [Errno 2] No such file or directory: '/Users/akira/Desktop/local/develop/pycheck/media/Screen_Shot_2021-05-03_AT_8.20.30.png'
2021-05-03 08:20:55,019 [ERROR] 14507 140578161735488 /home/pycheck/src/pycheck/pycheck/lib/python3.6/site-packages/django/utils/log.py:230 Internal Server Error: /skill/upload/heku/
Traceback (most recent call last):
  File "/home/pycheck/src/pycheck/pycheck/lib/python3.6/site-packages/django/core/handlers/exception.py", line 47, in inner
    response = get_response(request)
  File "/home/pycheck/src/pycheck/pycheck/lib/python3.6/site-packages/django/core/handlers/base.py", line 181, in _get_response
    response = wrapped_callback(request, *callback_args, **callback_kwargs)
  File "/home/pycheck/src/pycheck/skill/views.py", line 79, in upload
    username, question_number, question_level, answer_time, score = ocr(file_name)
  File "/home/pycheck/src/pycheck/skill/views.py", line 30, in ocr
    Image.open(f"/Users/akira/Desktop/local/develop/pycheck/media/{str(image_path)}"),
  File "/home/pycheck/src/pycheck/pycheck/lib/python3.6/site-packages/PIL/Image.py", line 2891, in open
    fp = builtins.open(filename, "rb")
FileNotFoundError: [Errno 2] No such file or directory: '/Users/akira/Desktop/local/develop/pycheck/media/Screen_Shot_2021-05-03_AT_8.20.48.png'
2021-05-03 08:27:21,696 [ERROR] 14759 139648329430848 /home/pycheck/src/pycheck/pycheck/lib/python3.6/site-packages/django/utils/log.py:230 Internal Server Error: /skill/upload/heku/
Traceback (most recent call last):
  File "/home/pycheck/src/pycheck/pycheck/lib/python3.6/site-packages/django/core/handlers/exception.py", line 47, in inner
    response = get_response(request)
  File "/home/pycheck/src/pycheck/pycheck/lib/python3.6/site-packages/django/core/handlers/base.py", line 181, in _get_response
    response = wrapped_callback(request, *callback_args, **callback_kwargs)
  File "/home/pycheck/src/pycheck/skill/views.py", line 79, in upload
    username, question_number, question_level, answer_time, score = ocr(file_name)
  File "/home/pycheck/src/pycheck/skill/views.py", line 30, in ocr
    Image.open(f"/Users/akira/Desktop/local/develop/pycheck/media/{str(image_path)}"),
  File "/home/pycheck/src/pycheck/pycheck/lib/python3.6/site-packages/PIL/Image.py", line 2891, in open
    fp = builtins.open(filename, "rb")
FileNotFoundError: [Errno 2] No such file or directory: '/Users/akira/Desktop/local/develop/pycheck/media/Screen_Shot_2021-05-03_AT_8.27.15.png'
2021-05-03 08:30:59,272 [ERROR] 14878 139916376532800 /home/pycheck/src/pycheck/pycheck/lib/python3.6/site-packages/django/utils/log.py:230 Internal Server Error: /skill/upload/heku/
Traceback (most recent call last):
  File "/home/pycheck/src/pycheck/pycheck/lib/python3.6/site-packages/django/core/handlers/exception.py", line 47, in inner
    response = get_response(request)
  File "/home/pycheck/src/pycheck/pycheck/lib/python3.6/site-packages/django/core/handlers/base.py", line 181, in _get_response
    response = wrapped_callback(request, *callback_args, **callback_kwargs)
  File "/home/pycheck/src/pycheck/skill/views.py", line 79, in upload
    username, question_number, question_level, answer_time, score = ocr(file_name)
  File "/home/pycheck/src/pycheck/skill/views.py", line 48, in ocr
    print(new_texts)
UnicodeEncodeError: 'latin-1' codec can't encode characters in position 10-15: ordinal not in range(256)
2021-05-03 08:34:54,766 [WARNING] 14992 140205482846016 /home/pycheck/src/pycheck/pycheck/lib/python3.6/site-packages/django/utils/log.py:230 Not Found: /account/login
2021-05-03 08:44:10,921 [INFO] 28412 8644521472 /opt/anaconda3/envs/local/lib/python3.8/site-packages/django/utils/autoreload.py:613 Watching for file changes with StatReloader
2021-05-03 08:59:12,402 [INFO] 28412 8644521472 /opt/anaconda3/envs/local/lib/python3.8/site-packages/django/utils/autoreload.py:236 /Users/akira/Desktop/local/develop/pycheck/gacha/urls.py changed, reloading.
2021-05-03 08:59:12,761 [INFO] 28992 8681217536 /opt/anaconda3/envs/local/lib/python3.8/site-packages/django/utils/autoreload.py:613 Watching for file changes with StatReloader
2021-05-03 09:14:33,561 [WARNING] 15720 139975129720640 /home/pycheck/src/pycheck/pycheck/lib/python3.6/site-packages/django/utils/log.py:230 Not Found: /gacha/gacha/
2021-05-03 09:15:52,228 [WARNING] 15720 139975129720640 /home/pycheck/src/pycheck/pycheck/lib/python3.6/site-packages/django/utils/log.py:230 Not Found: /
2021-05-03 09:17:21,347 [WARNING] 15812 140689439086400 /home/pycheck/src/pycheck/pycheck/lib/python3.6/site-packages/django/utils/log.py:230 Not Found: /gacha/gacha/
2021-05-03 09:52:45,280 [WARNING] 15812 140689439086400 /home/pycheck/src/pycheck/pycheck/lib/python3.6/site-packages/django/utils/log.py:230 Not Found: /favicon.ico
2021-05-03 09:52:46,325 [WARNING] 15812 140689439086400 /home/pycheck/src/pycheck/pycheck/lib/python3.6/site-packages/django/utils/log.py:230 Not Found: /
2021-05-03 09:52:54,514 [WARNING] 15812 140689439086400 /home/pycheck/src/pycheck/pycheck/lib/python3.6/site-packages/django/utils/log.py:230 Not Found: /
2021-05-03 09:53:12,421 [WARNING] 15812 140689439086400 /home/pycheck/src/pycheck/pycheck/lib/python3.6/site-packages/django/utils/log.py:230 Not Found: /robots.txt
2021-05-03 09:53:18,720 [WARNING] 15812 140689439086400 /home/pycheck/src/pycheck/pycheck/lib/python3.6/site-packages/django/utils/log.py:230 Not Found: /
2021-05-03 09:55:07,770 [WARNING] 15812 140689439086400 /home/pycheck/src/pycheck/pycheck/lib/python3.6/site-packages/django/utils/log.py:230 Not Found: /
2021-05-03 09:55:12,147 [WARNING] 15812 140689439086400 /home/pycheck/src/pycheck/pycheck/lib/python3.6/site-packages/django/utils/log.py:230 Not Found: /
2021-05-03 09:56:50,389 [WARNING] 15812 140689439086400 /home/pycheck/src/pycheck/pycheck/lib/python3.6/site-packages/django/utils/log.py:230 Not Found: /
2021-05-03 10:13:29,735 [ERROR] 16883 140492529252160 /home/pycheck/src/pycheck/pycheck/lib/python3.6/site-packages/django/utils/log.py:230 Internal Server Error: /gacha/gacha_item_list/heku/
Traceback (most recent call last):
  File "/home/pycheck/src/pycheck/pycheck/lib/python3.6/site-packages/django/core/handlers/exception.py", line 47, in inner
    response = get_response(request)
  File "/home/pycheck/src/pycheck/pycheck/lib/python3.6/site-packages/django/core/handlers/base.py", line 181, in _get_response
    response = wrapped_callback(request, *callback_args, **callback_kwargs)
  File "/home/pycheck/src/pycheck/gacha/views.py", line 74, in gacha_item_list
    item_names = GachaItem.objects.filter(username=username)
  File "/home/pycheck/src/pycheck/pycheck/lib/python3.6/site-packages/django/db/models/manager.py", line 85, in manager_method
    return getattr(self.get_queryset(), name)(*args, **kwargs)
  File "/home/pycheck/src/pycheck/pycheck/lib/python3.6/site-packages/django/db/models/query.py", line 942, in filter
    return self._filter_or_exclude(False, *args, **kwargs)
  File "/home/pycheck/src/pycheck/pycheck/lib/python3.6/site-packages/django/db/models/query.py", line 962, in _filter_or_exclude
    clone._filter_or_exclude_inplace(negate, *args, **kwargs)
  File "/home/pycheck/src/pycheck/pycheck/lib/python3.6/site-packages/django/db/models/query.py", line 969, in _filter_or_exclude_inplace
    self._query.add_q(Q(*args, **kwargs))
  File "/home/pycheck/src/pycheck/pycheck/lib/python3.6/site-packages/django/db/models/sql/query.py", line 1358, in add_q
    clause, _ = self._add_q(q_object, self.used_aliases)
  File "/home/pycheck/src/pycheck/pycheck/lib/python3.6/site-packages/django/db/models/sql/query.py", line 1380, in _add_q
    split_subq=split_subq, check_filterable=check_filterable,
  File "/home/pycheck/src/pycheck/pycheck/lib/python3.6/site-packages/django/db/models/sql/query.py", line 1258, in build_filter
    lookups, parts, reffed_expression = self.solve_lookup_type(arg)
  File "/home/pycheck/src/pycheck/pycheck/lib/python3.6/site-packages/django/db/models/sql/query.py", line 1084, in solve_lookup_type
    _, field, _, lookup_parts = self.names_to_path(lookup_splitted, self.get_meta())
  File "/home/pycheck/src/pycheck/pycheck/lib/python3.6/site-packages/django/db/models/sql/query.py", line 1482, in names_to_path
    "Choices are: %s" % (name, ", ".join(available)))
django.core.exceptions.FieldError: Cannot resolve keyword 'username' into field. Choices are: id, image, name, rare, title, title_id
2021-05-03 10:13:34,773 [ERROR] 16883 140492529252160 /home/pycheck/src/pycheck/pycheck/lib/python3.6/site-packages/django/utils/log.py:230 Internal Server Error: /gacha/gacha_item_list/heku/
Traceback (most recent call last):
  File "/home/pycheck/src/pycheck/pycheck/lib/python3.6/site-packages/django/core/handlers/exception.py", line 47, in inner
    response = get_response(request)
  File "/home/pycheck/src/pycheck/pycheck/lib/python3.6/site-packages/django/core/handlers/base.py", line 181, in _get_response
    response = wrapped_callback(request, *callback_args, **callback_kwargs)
  File "/home/pycheck/src/pycheck/gacha/views.py", line 74, in gacha_item_list
    item_names = GachaItem.objects.filter(username=username)
  File "/home/pycheck/src/pycheck/pycheck/lib/python3.6/site-packages/django/db/models/manager.py", line 85, in manager_method
    return getattr(self.get_queryset(), name)(*args, **kwargs)
  File "/home/pycheck/src/pycheck/pycheck/lib/python3.6/site-packages/django/db/models/query.py", line 942, in filter
    return self._filter_or_exclude(False, *args, **kwargs)
  File "/home/pycheck/src/pycheck/pycheck/lib/python3.6/site-packages/django/db/models/query.py", line 962, in _filter_or_exclude
    clone._filter_or_exclude_inplace(negate, *args, **kwargs)
  File "/home/pycheck/src/pycheck/pycheck/lib/python3.6/site-packages/django/db/models/query.py", line 969, in _filter_or_exclude_inplace
    self._query.add_q(Q(*args, **kwargs))
  File "/home/pycheck/src/pycheck/pycheck/lib/python3.6/site-packages/django/db/models/sql/query.py", line 1358, in add_q
    clause, _ = self._add_q(q_object, self.used_aliases)
  File "/home/pycheck/src/pycheck/pycheck/lib/python3.6/site-packages/django/db/models/sql/query.py", line 1380, in _add_q
    split_subq=split_subq, check_filterable=check_filterable,
  File "/home/pycheck/src/pycheck/pycheck/lib/python3.6/site-packages/django/db/models/sql/query.py", line 1258, in build_filter
    lookups, parts, reffed_expression = self.solve_lookup_type(arg)
  File "/home/pycheck/src/pycheck/pycheck/lib/python3.6/site-packages/django/db/models/sql/query.py", line 1084, in solve_lookup_type
    _, field, _, lookup_parts = self.names_to_path(lookup_splitted, self.get_meta())
  File "/home/pycheck/src/pycheck/pycheck/lib/python3.6/site-packages/django/db/models/sql/query.py", line 1482, in names_to_path
    "Choices are: %s" % (name, ", ".join(available)))
django.core.exceptions.FieldError: Cannot resolve keyword 'username' into field. Choices are: id, image, name, rare, title, title_id
2021-05-03 11:37:18,666 [WARNING] 17807 139906264835904 /home/pycheck/src/pycheck/pycheck/lib/python3.6/site-packages/django/utils/log.py:230 Not Found: /ReportServer
2021-05-03 11:45:27,493 [WARNING] 17807 139906264835904 /home/pycheck/src/pycheck/pycheck/lib/python3.6/site-packages/django/utils/log.py:230 Not Found: /gacha/gacha/
2021-05-03 11:48:15,478 [WARNING] 17807 139906264835904 /home/pycheck/src/pycheck/pycheck/lib/python3.6/site-packages/django/utils/log.py:230 Not Found: /login
2021-05-03 11:49:20,121 [ERROR] 18199 140500360177472 /home/pycheck/src/pycheck/pycheck/lib/python3.6/site-packages/django/utils/log.py:230 Internal Server Error: /gacha/gacha_item_list/heku/
Traceback (most recent call last):
  File "/home/pycheck/src/pycheck/pycheck/lib/python3.6/site-packages/django/core/handlers/exception.py", line 47, in inner
    response = get_response(request)
  File "/home/pycheck/src/pycheck/pycheck/lib/python3.6/site-packages/django/core/handlers/base.py", line 181, in _get_response
    response = wrapped_callback(request, *callback_args, **callback_kwargs)
  File "/home/pycheck/src/pycheck/gacha/views.py", line 77, in gacha_item_list
    gacha_item = GachaItem.objects.get(name=item_name.name)
AttributeError: 'MyGachaItems' object has no attribute 'name'
2021-05-03 12:08:06,548 [WARNING] 18412 140074825258816 /home/pycheck/src/pycheck/pycheck/lib/python3.6/site-packages/django/utils/log.py:230 Not Found: /wp-login.php
2021-05-03 12:40:53,942 [WARNING] 18412 140074825258816 /home/pycheck/src/pycheck/pycheck/lib/python3.6/site-packages/django/utils/log.py:230 Not Found: /vendor/phpunit/phpunit/src/Util/PHP/eval-stdin.php
2021-05-03 12:40:54,312 [WARNING] 18412 140074825258816 /home/pycheck/src/pycheck/pycheck/lib/python3.6/site-packages/django/utils/log.py:230 Not Found: /api/jsonws/invoke
2021-05-03 12:40:54,955 [WARNING] 18412 140074825258816 /home/pycheck/src/pycheck/pycheck/lib/python3.6/site-packages/django/utils/log.py:230 Not Found: /solr/admin/info/system
2021-05-03 12:40:56,699 [WARNING] 18412 140074825258816 /home/pycheck/src/pycheck/pycheck/lib/python3.6/site-packages/django/utils/log.py:230 Not Found: /
2021-05-03 12:40:57,497 [WARNING] 18412 140074825258816 /home/pycheck/src/pycheck/pycheck/lib/python3.6/site-packages/django/utils/log.py:230 Not Found: /index.php
2021-05-03 12:40:57,580 [WARNING] 18412 140074825258816 /home/pycheck/src/pycheck/pycheck/lib/python3.6/site-packages/django/utils/log.py:230 Not Found: /
2021-05-03 12:40:58,378 [WARNING] 18412 140074825258816 /home/pycheck/src/pycheck/pycheck/lib/python3.6/site-packages/django/utils/log.py:230 Not Found: /console/
2021-05-03 12:40:59,522 [WARNING] 18412 140074825258816 /home/pycheck/src/pycheck/pycheck/lib/python3.6/site-packages/django/utils/log.py:230 Not Found: /wp-content/plugins/wp-file-manager/readme.txt
2021-05-03 12:41:00,483 [WARNING] 18412 140074825258816 /home/pycheck/src/pycheck/pycheck/lib/python3.6/site-packages/django/utils/log.py:230 Not Found: /vendor/phpunit/phpunit/src/Util/PHP/eval-stdin.php
2021-05-03 12:41:00,670 [WARNING] 18412 140074825258816 /home/pycheck/src/pycheck/pycheck/lib/python3.6/site-packages/django/utils/log.py:230 Not Found: /_ignition/execute-solution
2021-05-03 12:41:01,279 [WARNING] 18412 140074825258816 /home/pycheck/src/pycheck/pycheck/lib/python3.6/site-packages/django/utils/log.py:230 Not Found: /Autodiscover/Autodiscover.xml
2021-05-03 13:45:39,773 [WARNING] 18412 140074825258816 /home/pycheck/src/pycheck/pycheck/lib/python3.6/site-packages/django/utils/log.py:230 Not Found: /
2021-05-03 13:45:40,308 [WARNING] 18412 140074825258816 /home/pycheck/src/pycheck/pycheck/lib/python3.6/site-packages/django/utils/log.py:230 Not Found: /robots.txt
2021-05-03 13:59:25,422 [WARNING] 18412 140074825258816 /home/pycheck/src/pycheck/pycheck/lib/python3.6/site-packages/django/utils/log.py:230 Not Found: /robots.txt
2021-05-03 13:59:26,584 [WARNING] 18412 140074825258816 /home/pycheck/src/pycheck/pycheck/lib/python3.6/site-packages/django/utils/log.py:230 Not Found: /
2021-05-03 14:13:23,311 [WARNING] 18412 140074825258816 /home/pycheck/src/pycheck/pycheck/lib/python3.6/site-packages/django/utils/log.py:230 Not Found: /owa/auth/logon.aspx
2021-05-03 14:31:39,892 [WARNING] 18412 140074825258816 /home/pycheck/src/pycheck/pycheck/lib/python3.6/site-packages/django/utils/log.py:230 Not Found: /
2021-05-03 14:44:39,315 [WARNING] 18412 140074825258816 /home/pycheck/src/pycheck/pycheck/lib/python3.6/site-packages/django/utils/log.py:230 Not Found: /
2021-05-03 15:11:02,054 [WARNING] 18412 140074825258816 /home/pycheck/src/pycheck/pycheck/lib/python3.6/site-packages/django/utils/log.py:230 Not Found: /
2021-05-03 15:36:50,891 [WARNING] 18412 140074825258816 /home/pycheck/src/pycheck/pycheck/lib/python3.6/site-packages/django/utils/log.py:230 Not Found: /actuator/health
2021-05-03 15:48:53,934 [WARNING] 18412 140074825258816 /home/pycheck/src/pycheck/pycheck/lib/python3.6/site-packages/django/utils/log.py:230 Not Found: /
2021-05-03 16:28:46,199 [WARNING] 18412 140074825258816 /home/pycheck/src/pycheck/pycheck/lib/python3.6/site-packages/django/utils/log.py:230 Not Found: /
2021-05-03 17:18:21,771 [WARNING] 18412 140074825258816 /home/pycheck/src/pycheck/pycheck/lib/python3.6/site-packages/django/utils/log.py:230 Not Found: /
2021-05-03 17:35:42,893 [WARNING] 18412 140074825258816 /home/pycheck/src/pycheck/pycheck/lib/python3.6/site-packages/django/utils/log.py:230 Not Found: /
2021-05-03 18:46:08,785 [WARNING] 18412 140074825258816 /home/pycheck/src/pycheck/pycheck/lib/python3.6/site-packages/django/utils/log.py:230 Not Found: /
2021-05-03 19:54:20,323 [WARNING] 18412 140074825258816 /home/pycheck/src/pycheck/pycheck/lib/python3.6/site-packages/django/utils/log.py:230 Not Found: /
2021-05-03 19:59:04,946 [WARNING] 18412 140074825258816 /home/pycheck/src/pycheck/pycheck/lib/python3.6/site-packages/django/utils/log.py:230 Not Found: /
2021-05-04 00:13:23,451 [WARNING] 18412 140074825258816 /home/pycheck/src/pycheck/pycheck/lib/python3.6/site-packages/django/utils/log.py:230 Not Found: /owa/
2021-05-04 00:24:23,554 [WARNING] 18412 140074825258816 /home/pycheck/src/pycheck/pycheck/lib/python3.6/site-packages/django/utils/log.py:230 Not Found: /
2021-05-04 00:44:58,371 [WARNING] 18412 140074825258816 /home/pycheck/src/pycheck/pycheck/lib/python3.6/site-packages/django/utils/log.py:230 Not Found: /
2021-05-04 03:15:49,818 [WARNING] 18412 140074825258816 /home/pycheck/src/pycheck/pycheck/lib/python3.6/site-packages/django/utils/log.py:230 Not Found: /
2021-05-04 04:16:14,409 [WARNING] 18412 140074825258816 /home/pycheck/src/pycheck/pycheck/lib/python3.6/site-packages/django/utils/log.py:230 Not Found: /
2021-05-04 05:02:59,861 [WARNING] 18412 140074825258816 /home/pycheck/src/pycheck/pycheck/lib/python3.6/site-packages/django/utils/log.py:230 Not Found: /
2021-05-04 05:18:50,963 [WARNING] 18412 140074825258816 /home/pycheck/src/pycheck/pycheck/lib/python3.6/site-packages/django/utils/log.py:230 Not Found: /
2021-05-04 05:58:18,733 [WARNING] 18412 140074825258816 /home/pycheck/src/pycheck/pycheck/lib/python3.6/site-packages/django/utils/log.py:230 Not Found: /index.php
2021-05-04 05:58:18,751 [WARNING] 18412 140074825258816 /home/pycheck/src/pycheck/pycheck/lib/python3.6/site-packages/django/utils/log.py:230 Not Found: /
2021-05-04 05:58:22,944 [WARNING] 18412 140074825258816 /home/pycheck/src/pycheck/pycheck/lib/python3.6/site-packages/django/utils/log.py:230 Not Found: /mifs/.;/services/LogService
2021-05-04 05:58:22,975 [WARNING] 18412 140074825258816 /home/pycheck/src/pycheck/pycheck/lib/python3.6/site-packages/django/utils/log.py:230 Not Found: /wp-content/plugins/wp-file-manager/readme.txt
2021-05-04 05:58:27,524 [WARNING] 18412 140074825258816 /home/pycheck/src/pycheck/pycheck/lib/python3.6/site-packages/django/utils/log.py:230 Not Found: /console/
2021-05-04 05:58:30,424 [WARNING] 18412 140074825258816 /home/pycheck/src/pycheck/pycheck/lib/python3.6/site-packages/django/utils/log.py:230 Not Found: /vendor/phpunit/phpunit/src/Util/PHP/eval-stdin.php
2021-05-04 05:58:33,873 [WARNING] 18412 140074825258816 /home/pycheck/src/pycheck/pycheck/lib/python3.6/site-packages/django/utils/log.py:230 Not Found: /api/jsonws/invoke
2021-05-04 05:58:34,826 [WARNING] 18412 140074825258816 /home/pycheck/src/pycheck/pycheck/lib/python3.6/site-packages/django/utils/log.py:230 Not Found: /Autodiscover/Autodiscover.xml
2021-05-04 05:58:36,755 [WARNING] 18412 140074825258816 /home/pycheck/src/pycheck/pycheck/lib/python3.6/site-packages/django/utils/log.py:230 Not Found: /vendor/phpunit/phpunit/src/Util/PHP/eval-stdin.php
2021-05-04 06:26:11,468 [WARNING] 18412 140074825258816 /home/pycheck/src/pycheck/pycheck/lib/python3.6/site-packages/django/utils/log.py:230 Not Found: /.git/config
2021-05-04 07:55:09,978 [WARNING] 18412 140074825258816 /home/pycheck/src/pycheck/pycheck/lib/python3.6/site-packages/django/utils/log.py:230 Not Found: /Telerik.Web.UI.WebResource.axd
2021-05-04 08:00:26,973 [WARNING] 18412 140074825258816 /home/pycheck/src/pycheck/pycheck/lib/python3.6/site-packages/django/utils/log.py:230 Not Found: /
2021-05-04 08:33:41,122 [WARNING] 18412 140074825258816 /home/pycheck/src/pycheck/pycheck/lib/python3.6/site-packages/django/utils/log.py:230 Not Found: /
2021-05-04 08:34:23,374 [WARNING] 18412 140074825258816 /home/pycheck/src/pycheck/pycheck/lib/python3.6/site-packages/django/utils/log.py:230 Not Found: /
2021-05-04 08:34:27,938 [WARNING] 18412 140074825258816 /home/pycheck/src/pycheck/pycheck/lib/python3.6/site-packages/django/utils/log.py:230 Not Found: /
2021-05-04 09:15:21,218 [WARNING] 18412 140074825258816 /home/pycheck/src/pycheck/pycheck/lib/python3.6/site-packages/django/utils/log.py:230 Not Found: /wp-content/plugins/wp-file-manager/readme.txt
2021-05-04 09:15:23,543 [WARNING] 18412 140074825258816 /home/pycheck/src/pycheck/pycheck/lib/python3.6/site-packages/django/utils/log.py:230 Not Found: /vendor/phpunit/phpunit/src/Util/PHP/eval-stdin.php
2021-05-04 09:15:23,675 [WARNING] 18412 140074825258816 /home/pycheck/src/pycheck/pycheck/lib/python3.6/site-packages/django/utils/log.py:230 Not Found: /api/jsonws/invoke
2021-05-04 09:15:24,446 [WARNING] 18412 140074825258816 /home/pycheck/src/pycheck/pycheck/lib/python3.6/site-packages/django/utils/log.py:230 Not Found: /solr/admin/info/system
2021-05-04 09:15:25,412 [WARNING] 18412 140074825258816 /home/pycheck/src/pycheck/pycheck/lib/python3.6/site-packages/django/utils/log.py:230 Not Found: /
2021-05-04 09:15:26,214 [WARNING] 18412 140074825258816 /home/pycheck/src/pycheck/pycheck/lib/python3.6/site-packages/django/utils/log.py:230 Not Found: /
2021-05-04 09:15:26,302 [WARNING] 18412 140074825258816 /home/pycheck/src/pycheck/pycheck/lib/python3.6/site-packages/django/utils/log.py:230 Not Found: /Autodiscover/Autodiscover.xml
2021-05-04 09:15:27,449 [WARNING] 18412 140074825258816 /home/pycheck/src/pycheck/pycheck/lib/python3.6/site-packages/django/utils/log.py:230 Not Found: /_ignition/execute-solution
2021-05-04 09:15:27,509 [WARNING] 18412 140074825258816 /home/pycheck/src/pycheck/pycheck/lib/python3.6/site-packages/django/utils/log.py:230 Not Found: /console/
2021-05-04 09:15:28,319 [WARNING] 18412 140074825258816 /home/pycheck/src/pycheck/pycheck/lib/python3.6/site-packages/django/utils/log.py:230 Not Found: /vendor/phpunit/phpunit/src/Util/PHP/eval-stdin.php
2021-05-04 09:15:28,478 [WARNING] 18412 140074825258816 /home/pycheck/src/pycheck/pycheck/lib/python3.6/site-packages/django/utils/log.py:230 Not Found: /index.php
2021-05-04 09:25:37,852 [WARNING] 2523 139917453653824 /home/pycheck/src/pycheck/pycheck/lib/python3.6/site-packages/django/utils/log.py:230 Not Found: /
2021-05-04 09:31:29,227 [WARNING] 2523 139917453653824 /home/pycheck/src/pycheck/pycheck/lib/python3.6/site-packages/django/utils/log.py:230 Not Found: /Telerik.Web.UI.WebResource.axd
2021-05-04 10:05:09,290 [WARNING] 2523 139917453653824 /home/pycheck/src/pycheck/pycheck/lib/python3.6/site-packages/django/utils/log.py:230 Not Found: /
2021-05-04 10:34:23,197 [ERROR] 3551 139839038879552 /home/pycheck/src/pycheck/pycheck/lib/python3.6/site-packages/django/utils/log.py:230 Internal Server Error: /gacha/gacha_item_list/heku/
Traceback (most recent call last):
  File "/home/pycheck/src/pycheck/pycheck/lib/python3.6/site-packages/django/core/handlers/exception.py", line 47, in inner
    response = get_response(request)
  File "/home/pycheck/src/pycheck/pycheck/lib/python3.6/site-packages/django/core/handlers/base.py", line 181, in _get_response
    response = wrapped_callback(request, *callback_args, **callback_kwargs)
  File "/home/pycheck/src/pycheck/gacha/views.py", line 84, in gacha_item_list
    gacha_item = GachaItem.objects.get(name=item_name.item)
  File "/home/pycheck/src/pycheck/pycheck/lib/python3.6/site-packages/django/db/models/manager.py", line 85, in manager_method
    return getattr(self.get_queryset(), name)(*args, **kwargs)
  File "/home/pycheck/src/pycheck/pycheck/lib/python3.6/site-packages/django/db/models/query.py", line 431, in get
    self.model._meta.object_name
gacha.models.GachaItem.DoesNotExist: GachaItem matching query does not exist.
2021-05-04 10:34:28,684 [ERROR] 3551 139839038879552 /home/pycheck/src/pycheck/pycheck/lib/python3.6/site-packages/django/utils/log.py:230 Internal Server Error: /gacha/gacha_item_list/heku/
Traceback (most recent call last):
  File "/home/pycheck/src/pycheck/pycheck/lib/python3.6/site-packages/django/core/handlers/exception.py", line 47, in inner
    response = get_response(request)
  File "/home/pycheck/src/pycheck/pycheck/lib/python3.6/site-packages/django/core/handlers/base.py", line 181, in _get_response
    response = wrapped_callback(request, *callback_args, **callback_kwargs)
  File "/home/pycheck/src/pycheck/gacha/views.py", line 84, in gacha_item_list
    gacha_item = GachaItem.objects.get(name=item_name.item)
  File "/home/pycheck/src/pycheck/pycheck/lib/python3.6/site-packages/django/db/models/manager.py", line 85, in manager_method
    return getattr(self.get_queryset(), name)(*args, **kwargs)
  File "/home/pycheck/src/pycheck/pycheck/lib/python3.6/site-packages/django/db/models/query.py", line 431, in get
    self.model._meta.object_name
gacha.models.GachaItem.DoesNotExist: GachaItem matching query does not exist.
2021-05-04 10:36:25,542 [WARNING] 3551 139839038879552 /home/pycheck/src/pycheck/pycheck/lib/python3.6/site-packages/django/utils/log.py:230 Not Found: /gacha/gacha/
2021-05-04 10:36:33,157 [WARNING] 3551 139839038879552 /home/pycheck/src/pycheck/pycheck/lib/python3.6/site-packages/django/utils/log.py:230 Not Found: /
2021-05-04 10:49:15,975 [WARNING] 3716 139794175444800 /home/pycheck/src/pycheck/pycheck/lib/python3.6/site-packages/django/utils/log.py:230 Not Found: /robots.txt
2021-05-04 10:49:17,154 [WARNING] 3716 139794175444800 /home/pycheck/src/pycheck/pycheck/lib/python3.6/site-packages/django/utils/log.py:230 Not Found: /
2021-05-04 11:08:28,219 [WARNING] 4199 140532310759232 /home/pycheck/src/pycheck/pycheck/lib/python3.6/site-packages/django/utils/log.py:230 Not Found: /gacha/gacha/
2021-05-04 11:12:10,353 [WARNING] 4199 140532310759232 /home/pycheck/src/pycheck/pycheck/lib/python3.6/site-packages/django/utils/log.py:230 Not Found: /api/v2/ajax
2021-05-04 11:26:01,919 [WARNING] 4390 140428886644544 /home/pycheck/src/pycheck/pycheck/lib/python3.6/site-packages/django/utils/log.py:230 Not Found: /
2021-05-04 11:55:22,912 [WARNING] 4718 140387729946432 /home/pycheck/src/pycheck/pycheck/lib/python3.6/site-packages/django/utils/log.py:230 Not Found: /ecp/Current/exporttool/microsoft.exchange.ediscovery.exporttool.application
2021-05-04 11:58:20,644 [WARNING] 4718 140387729946432 /home/pycheck/src/pycheck/pycheck/lib/python3.6/site-packages/django/utils/log.py:230 Not Found: /remote/login
2021-05-04 12:08:55,250 [WARNING] 5068 140240766093120 /home/pycheck/src/pycheck/pycheck/lib/python3.6/site-packages/django/utils/log.py:230 Not Found: /gacha/gacha/
